Traceback (most recent call last):
  File "/opt/hostedtoolcache/Python/3.7.12/x64/lib/python3.7/site-packages/jupyter_cache/executors/utils.py", line 56, in single_nb_execution
    record_timing=False,
  File "/opt/hostedtoolcache/Python/3.7.12/x64/lib/python3.7/site-packages/nbclient/client.py", line 1093, in execute
    return NotebookClient(nb=nb, resources=resources, km=km, **kwargs).execute()
  File "/opt/hostedtoolcache/Python/3.7.12/x64/lib/python3.7/site-packages/nbclient/util.py", line 84, in wrapped
    return just_run(coro(*args, **kwargs))
  File "/opt/hostedtoolcache/Python/3.7.12/x64/lib/python3.7/site-packages/nbclient/util.py", line 62, in just_run
    return loop.run_until_complete(coro)
  File "/opt/hostedtoolcache/Python/3.7.12/x64/lib/python3.7/asyncio/base_events.py", line 587, in run_until_complete
    return future.result()
  File "/opt/hostedtoolcache/Python/3.7.12/x64/lib/python3.7/site-packages/nbclient/client.py", line 560, in async_execute
    cell, index, execution_count=self.code_cells_executed + 1
  File "/opt/hostedtoolcache/Python/3.7.12/x64/lib/python3.7/site-packages/nbclient/client.py", line 854, in async_execute_cell
    self._check_raise_for_error(cell, exec_reply)
  File "/opt/hostedtoolcache/Python/3.7.12/x64/lib/python3.7/site-packages/nbclient/client.py", line 756, in _check_raise_for_error
    raise CellExecutionError.from_cell_and_msg(cell, exec_reply_content)
nbclient.exceptions.CellExecutionError: An error occurred while executing the following cell:
------------------
df = generate_spikes_stim_strength(mouse_response_slopes=np.arange(5, 40, 5),
                                   n_trials=20,
                                   n_neurons=6,
                                   n_mice=3,
                                   dur=5,
                                   # mouse_response_slope=40,
                                   overall_stim_response_strength=5)

------------------

[0;31m---------------------------------------------------------------------------[0m
[0;31mTypeError[0m                                 Traceback (most recent call last)
[0;32m/tmp/ipykernel_8284/3547085448.py[0m in [0;36m<module>[0;34m[0m
[1;32m      5[0m                                    [0mdur[0m[0;34m=[0m[0;36m5[0m[0;34m,[0m[0;34m[0m[0;34m[0m[0m
[1;32m      6[0m                                    [0;31m# mouse_response_slope=40,[0m[0;34m[0m[0;34m[0m[0;34m[0m[0m
[0;32m----> 7[0;31m                                    overall_stim_response_strength=5)
[0m
[0;32m/opt/hostedtoolcache/Python/3.7.12/x64/lib/python3.7/site-packages/bayes_window/generative_models.py[0m in [0;36mgenerate_spikes_stim_strength[0;34m(overall_stim_response_strengths, **kwargs)[0m
[1;32m     62[0m     [0mdf[0m [0;34m=[0m [0;34m[[0m[0;34m][0m[0;34m[0m[0;34m[0m[0m
[1;32m     63[0m     [0;32mfor[0m [0moverall_stim_response_strength[0m [0;32min[0m [0moverall_stim_response_strengths[0m[0;34m:[0m[0;34m[0m[0;34m[0m[0m
[0;32m---> 64[0;31m         [0mdf1[0m [0;34m=[0m [0mgenerate_fake_spikes[0m[0;34m([0m[0moverall_stim_response_strength[0m[0;34m=[0m[0moverall_stim_response_strength[0m[0;34m,[0m [0;34m**[0m[0mkwargs[0m[0;34m)[0m[0;34m[[0m[0;36m0[0m[0;34m][0m[0;34m[0m[0;34m[0m[0m
[0m[1;32m     65[0m         [0mdf1[0m[0;34m.[0m[0minsert[0m[0;34m([0m[0;36m0[0m[0;34m,[0m [0;34m'stim_strength'[0m[0;34m,[0m [0mdf1[0m[0;34m[[0m[0;34m'stim'[0m[0;34m][0m [0;34m*[0m [0moverall_stim_response_strength[0m[0;34m)[0m[0;34m[0m[0;34m[0m[0m
[1;32m     66[0m         [0mdf[0m[0;34m.[0m[0mappend[0m[0;34m([0m[0mdf1[0m[0;34m)[0m[0;34m[0m[0;34m[0m[0m

[0;31mTypeError[0m: generate_fake_spikes() got multiple values for keyword argument 'overall_stim_response_strength'
TypeError: generate_fake_spikes() got multiple values for keyword argument 'overall_stim_response_strength'

